Workbook
Name SegmentaciónDeDatos_ASESOR: #N/A
Name SegmentaciónDeDatos_ASESOR1: #N/A

Sheet PLANTILLA- VOLUMEN DE VENTAS
A1: MES | B1: VENTAS 2024 (KG) | C1: VENTAS 2024 (S/.) | D1: VENTAS OBJETIVO (KG) | E1: VENTAS REALIZADAS(KG) | F1: DIFERENCIA (KG) | G1: VENTAS OBJETIVO (S/.) | H1: VENTAS REALIZADAS(S/.) | I1: DIFERENCIA(S/.) | J1: CUMPLIMIENTO KG(%) | K1: CUMPLIMIENTO S/.(%)
A2: Enero | B2: 45942.89 | C2: 2579667 | D2: =B2+20%*B2 -> 55131.468 | E2: =GETPIVOTDATA("CANTIDAD (KG)",'COMPARATIVO MENSUAL 2025'!$B$20,"MES","ENERO") -> 66503.46 | F2: =E2-D2 -> 11371.992 | G2: =C2+20%*C2 -> 3095600.4 | H2: =GETPIVOTDATA("IMPORTE (S/.)",'COMPARATIVO MENSUAL 2025'!$B$3,"MES","ENERO") -> 2569941 | I2: =H2-G2 -> -525659.37 | J2: =E2/D2 -> 1.2062704 | K2: =H2/G2 -> 0.83019146
A3: Febrero | B3: 73172.04 | C3: 3443322.8 | D3: =B3+20%*B3 -> 87806.448 | E3: =GETPIVOTDATA("CANTIDAD (KG)",'COMPARATIVO MENSUAL 2025'!$B$20,"MES","FEBRERO") -> 75073.55 | F3: =E3-D3 -> -12732.898 | G3: =C3+20%*C3 -> 4131987.4 | H3: =GETPIVOTDATA("IMPORTE (S/.)",'COMPARATIVO MENSUAL 2025'!$B$3,"MES","FEBRERO") -> 2827362.1 | I3: =H3-G3 -> -1304625.3 | J3: =E3/D3 -> 0.85498903 | K3: =H3/G3 -> 0.68426204
A4: Marzo | B4: 77251.75 | C4: 3256508.9 | D4: =B4+20%*B4 -> 92702.1 | E4: =GETPIVOTDATA("CANTIDAD (KG)",'COMPARATIVO MENSUAL 2025'!$B$20,"MES","MARZO") -> #REF! | F4: =E4-D4 -> #REF! | G4: =C4+20%*C4 -> 3907810.7 | H4: =GETPIVOTDATA("IMPORTE (S/.)",'COMPARATIVO MENSUAL 2025'!$B$3,"MES","MARZO") -> #REF! | I4: =H4-G4 -> #REF! | J4: =E4/D4 -> #REF! | K4: =H4/G4 -> #REF!
A5: Abril | B5: 87655.51 | C5: 4058295.9 | D5: =B5+20%*B5 -> 105186.61 | E5: =GETPIVOTDATA("CANTIDAD (KG)",'COMPARATIVO MENSUAL 2025'!$B$20,"MES","ABRIL") -> #REF! | F5: =E5-D5 -> #REF! | G5: =C5+20%*C5 -> 4869955.1 | H5: =GETPIVOTDATA("IMPORTE (S/.)",'COMPARATIVO MENSUAL 2025'!$B$3,"MES","ABRIL") -> #REF! | I5: =H5-G5 -> #REF! | J5: =E5/D5 -> #REF! | K5: =H5/G5 -> #REF!
A6: Mayo | B6: 96801.06 | C6: 4271469.5 | D6: =B6+20%*B6 -> 116161.27 | E6: =GETPIVOTDATA("CANTIDAD (KG)",'COMPARATIVO MENSUAL 2025'!$B$20,"MES","MAYO") -> #REF! | F6: =E6-D6 -> #REF! | G6: =C6+20%*C6 -> 5125763.5 | H6: =GETPIVOTDATA("IMPORTE (S/.)",'COMPARATIVO MENSUAL 2025'!$B$3,"MES","MAYO") -> #REF! | I6: =H6-G6 -> #REF! | J6: =E6/D6 -> #REF! | K6: =H6/G6 -> #REF!
A7: Junio | B7: 84485.29 | C7: 3680527.3 | D7: =B7+20%*B7 -> 101382.35 | E7: =GETPIVOTDATA("CANTIDAD (KG)",'COMPARATIVO MENSUAL 2025'!$B$20,"MES","JUNIO") -> #REF! | G7: =C7+20%*C7 -> 4416632.8 | H7: =GETPIVOTDATA("IMPORTE (S/.)",'COMPARATIVO MENSUAL 2025'!$B$3,"MES","JUNIO") -> #REF!
A8: Julio | B8: 93512.75 | C8: 4138506.1 | D8: =B8+20%*B8 -> 112215.3 | E8: =GETPIVOTDATA("CANTIDAD (KG)",'COMPARATIVO MENSUAL 2025'!$B$20,"MES","JULIO") -> #REF! | G8: =C8+20%*C8 -> 4966207.3 | H8: =GETPIVOTDATA("IMPORTE (S/.)",'COMPARATIVO MENSUAL 2025'!$B$3,"MES","JULIO") -> #REF!
A9: Agosto | B9: 88751.43 | C9: 4097126 | D9: =B9+20%*B9 -> 106501.72 | E9: =GETPIVOTDATA("CANTIDAD (KG)",'COMPARATIVO MENSUAL 2025'!$B$20,"MES","AGOSTO") -> #REF! | G9: =C9+20%*C9 -> 4916551.3 | H9: =GETPIVOTDATA("IMPORTE (S/.)",'COMPARATIVO MENSUAL 2025'!$B$3,"MES","AGOSTO") -> #REF!
A10: Setiembre | B10: 76376.16 | C10: 3604570.9 | D10: =B10+20%*B10 -> 91651.392 | G10: =C10+20%*C10 -> 4325485
A11: Octubre | B11: 85546.21 | C11: 4131005.8 | D11: =B11+20%*B11 -> 102655.45 | G11: =C11+20%*C11 -> 4957207
A12: Noviembre | B12: 81675.31 | C12: 3949812.4 | D12: =B12+20%*B12 -> 98010.372 | G12: =C12+20%*C12 -> 4739774.8
A13: Diciembre | B13: 64346.35 | C13: 2988692.8 | D13: =B13+20%*B13 -> 77215.62 | G13: =C13+20%*C13 -> 3586431.4

Sheet COMPARATIVO MENSUAL 2025
B2: MES DE OCTUBRE
B3: IMPORTE (S/.) POR ASESOR | C3: ASESOR
B4: MES | C4: ALFREDO ASTOQUILLCA | D4: ANTONIO CHAVEZ | E4: DIANA MARCOS | F4: CRIS ARMAS | G4: Total general
B5: ENERO | C5: 622444.2 | D5: 1217789.8 | E5: 673049.92 | F5: 56657.09 | G5: 2569941
B6: FEBRERO | C6: 770345.13 | D6: 1066540.7 | E6: 868765.75 | F6: 121710.55 | G6: 2827362.1
B7: Total general | C7: 1392789.3 | D7: 2284330.5 | E7: 1541815.7 | F7: 178367.64 | G7: 5397303.2
B17: Anàlisis s/.: | C17: 0.74 | D17: 0.18 | E17: 0.28
B20: CANTIDAD (KG) POR ASESOR | C20: ASESOR
B21: MES | C21: ALFREDO ASTOQUILLCA | D21: ANTONIO CHAVEZ | E21: DIANA MARCOS | F21: CRIS ARMAS | G21: Total general
B22: ENERO | C22: 20041.52 | D22: 25654.98 | E22: 19969 | F22: 837.96 | G22: 66503.46
B23: FEBRERO | C23: 24654.9 | D23: 24924.75 | E23: 23026.92 | F23: 2466.98 | G23: 75073.55
B24: Total general | C24: 44696.42 | D24: 50579.73 | E24: 42995.92 | F24: 3304.94 | G24: 141577.01
B34: Anàlisis (kg): | C34: 0.51 | D34: 0.44 | E34: 0.05

Sheet Hoja1
A1: 435607.05 | B1: 1685945.1 | C1: 1003846.5 | D1: 745711.02 | F1: 3871109.7
A2: 770692.53 | C2: 1148786.2 | D2: 1056035.9 | E2: 616620.73 | F2: 3592135.3
A4: =+(A2-A1)/A1 -> 0.76923796 | B4: =+(B2-B1)/B1 -> -1 | C4: =+(C2-C1)/C1 -> 0.14438429 | D4: =+(D2-D1)/D1 -> 0.41614628 | E4: =+(E2-E1)/E1 -> #DIV/0!

Sheet INDICADORES COMERCIALES
A1: INDICADORES COMERCIALES 2026
A3: Suma de IMPORTE (S/.) | B3: MESES
A4: ASESOR | B4: ENERO | C4: FEBRERO | D4: MARZO | E4: ABRIL | F4: MAYO | G4: JUNIO | H4: JULIO | I4: AGOSTO | J4: SETIEMBRE | K4: OCTUBRE | L4: NOVIEMBRE | M4: DICIEMBRE | N4: Total general
A5: ANTONIO CHAVEZ | B5: 1217789.8 | C5: 1066540.7 | N5: 2284330.5
A6: DIANA MARCOS | B6: 673049.92 | C6: 868765.75 | N6: 1541815.7
A7: ALFREDO ASTOQUILLCA | B7: 622444.2 | C7: 770345.13 | N7: 1392789.3
A8: CRIS ARMAS | B8: 56657.09 | C8: 121710.55 | N8: 178367.64
A9: Total general | B9: 2569941 | C9: 2827362.1 | N9: 5397303.2
A12: Suma de CANTIDAD (KG) | B12: MESES
A13: ASESOR | B13: ENERO | C13: FEBRERO | D13: MARZO | E13: ABRIL | F13: MAYO | G13: JUNIO | H13: JULIO | I13: AGOSTO | J13: SETIEMBRE | K13: OCTUBRE | L13: NOVIEMBRE | M13: DICIEMBRE | N13: Total general
A14: ANTONIO CHAVEZ | B14: 25654.98 | C14: 24924.75 | D14: 252.54 | N14: 50832.27
A15: ALFREDO ASTOQUILLCA | B15: 20041.52 | C15: 24654.9 | N15: 44696.42
A16: DIANA MARCOS | B16: 19969 | C16: 23026.92 | D16: 407.26 | N16: 43403.18
A17: CRIS ARMAS | B17: 837.96 | C17: 2466.98 | D17: 192.92 | N17: 3497.86
A18: Total general | B18: 66503.46 | C18: 75073.55 | D18: 852.72 | N18: 142429.73

Sheet Hoja2
A1: INDICADORES COMERCIALES 2026
A3: Suma de IMPORTE (S/.) | B3: MESES
A4: ASESOR | B4: ENERO | C4: FEBRERO | D4: PROMEDIO | E4: ABRIL | F4: MAYO | G4: JUNIO | H4: JULIO | I4: AGOSTO | J4: SETIEMBRE | K4: OCTUBRE | L4: NOVIEMBRE | M4: DICIEMBRE | N4: Total general
A5: ANTONIO CHAVEZ | B5: 1217789.8 | C5: 1066540.7 | D5: =(B5+C5)/2 -> 1142165.3 | N5: 2284330.5
A6: DIANA MARCOS | B6: 673049.92 | C6: 868765.75 | D6: =(B6+C6)/2 -> 770907.83 | N6: 1541815.7
A7: CRIS ARMAS | B7: 622444.2 | C7: 770345.13 | D7: =(B7+C7)/2 -> 696394.67 | N7: 1392789.3
A8: ALFREDO ASTOQUILLCA | B8: 56657.09 | C8: 121710.55 | D8: =(B8+C8)/2 -> 89183.82 | N8: 178367.64
A9: Total general | B9: 2569941 | C9: 2827362.1 | N9: 5397303.2
A12: Suma de CANTIDAD (KG) | B12: MESES
A13: ASESOR | B13: ENERO | C13: FEBRERO | D13: PROMEDIO | E13: ABRIL | F13: MAYO | G13: JUNIO | H13: JULIO | I13: AGOSTO | J13: SETIEMBRE | K13: OCTUBRE | L13: NOVIEMBRE | M13: DICIEMBRE | N13: Total general
A14: ANTONIO CHAVEZ | B14: 25654.98 | C14: 24924.75 | D14: =(C14+B14)/2 -> 25289.865 | N14: 50832.27
A15: ALFREDO ASTOQUILLCA | B15: 10858.72 | C15: 24654.9 | D15: =(C15+B15)/2 -> 17756.81 | N15: 44696.42
A16: DIANA MARCOS | B16: 19969 | C16: 23026.92 | D16: =(C16+B16)/2 -> 21497.96 | N16: 43403.18
A17: CRIS ARMAS | B17: 10020 | C17: 2466.98 | D17: =(C17+B17)/2 -> 6243.49 | N17: 3497.86
A18: Total general | B18: 66502.7 | C18: 75073.55 | N18: 142429.73

Sheet DATA MENSUAL_ASESOR2026
A1: ASESOR | B1: MES | C1: IMPORTE (S/.) | D1: CANTIDAD (KG)
A2: ALFREDO ASTOQUILLCA | B2: ENERO | C2: 622444.2 | D2: 20041.52
A3: ALFREDO ASTOQUILLCA | B3: FEBRERO | C3: 770345.13 | D3: 24654.9
A4: ALFREDO ASTOQUILLCA | B4: MARZO
A5: ALFREDO ASTOQUILLCA | B5: ABRIL
A6: ALFREDO ASTOQUILLCA | B6: MAYO
A7: ALFREDO ASTOQUILLCA | B7: JUNIO
A8: ALFREDO ASTOQUILLCA | B8: JULIO
A9: ALFREDO ASTOQUILLCA | B9: AGOSTO
A10: ALFREDO ASTOQUILLCA | B10: SETIEMBRE
A11: ALFREDO ASTOQUILLCA | B11: OCTUBRE
A12: ALFREDO ASTOQUILLCA | B12: NOVIEMBRE
A13: ALFREDO ASTOQUILLCA | B13: DICIEMBRE
A14: CRIS ARMAS | B14: ENERO | C14: 56657.09 | D14: 837.96
A15: CRIS ARMAS | B15: FEBRERO | C15: 121710.55 | D15: 2466.98
A16: CRIS ARMAS | B16: MARZO | D16: 192.92
A17: CRIS ARMAS | B17: ABRIL
A18: CRIS ARMAS | B18: MAYO
A19: CRIS ARMAS | B19: JUNIO
A20: CRIS ARMAS | B20: JULIO
A21: CRIS ARMAS | B21: AGOSTO
A22: CRIS ARMAS | B22: SETIEMBRE
A23: CRIS ARMAS | B23: OCTUBRE
A24: CRIS ARMAS | B24: NOVIEMBRE
A25: CRIS ARMAS | B25: DICIEMBRE
A26: DIANA MARCOS | B26: ENERO | C26: 673049.92 | D26: 19969
A27: DIANA MARCOS | B27: FEBRERO | C27: 868765.75 | D27: 23026.92
A28: DIANA MARCOS | B28: MARZO | D28: 407.26
A29: DIANA MARCOS | B29: ABRIL
A30: DIANA MARCOS | B30: MAYO
A31: DIANA MARCOS | B31: JUNIO
A32: DIANA MARCOS | B32: JULIO
A33: DIANA MARCOS | B33: AGOSTO
A34: DIANA MARCOS | B34: SETIEMBRE
A35: DIANA MARCOS | B35: OCTUBRE
A36: DIANA MARCOS | B36: NOVIEMBRE
A37: DIANA MARCOS | B37: DICIEMBRE
A38: ANTONIO CHAVEZ | B38: ENERO | C38: 1217789.8 | D38: 25654.98
A39: ANTONIO CHAVEZ | B39: FEBRERO | C39: 1066540.7 | D39: 24924.75
A40: ANTONIO CHAVEZ | B40: MARZO | D40: 22679.07
...

Sheet 2026
A1: 2026
A3: ANTONIO CHAVEZ
A4: ACTUALMENTE
A5: Suma de IMPORTE (S/.) | B5: MESES
A6: ASESOR | B6: ENERO | C6: FEBRERO
A7: ANTONIO CHAVEZ | B7: 1217789.8 | C7: 1066540.7
A9: CLIENTES TRASPASADOS
A10: CORPORACION ALIMENTARIA SUIZA | B10: 7960.74 | C10: 42607.84
A11: FIBRAS UNIDAS | B11: 32722.31 | C11: 36438.57
A12: MISHA AND PUFF | C12: 1950.72
A13: SISTER KIDS | B13: 7841.55
A14: TEXGROUP | B14: 53870.06 | C14: 51404.78
A15: TEXTIL DEL VALLE | B15: 31190.73 | C15: 102102.14
A16: TEXTIL BABY FASHION | B16: 4190.2
B17: =SUM(B10:B16) -> 137775.59 | C17: =SUM(C10:C16) -> 234504.05
A19: QUITANDO LOS CLIENTES
A20: Suma de IMPORTE (S/.) | B20: MESES
A21: ASESOR | B21: ENERO | C21: FEBRERO
A22: ANTONIO CHAVEZ | B22: =+B7-B17 -> 1080014.2 | C22: =+C7-C17 -> 832036.65
A26: DIANA MARCOS
A27: ACTUALMENTE
A28: Suma de IMPORTE (S/.) | B28: MESES
A29: ASESOR | B29: ENERO | C29: FEBRERO
A30: DIANA MARCOS | B30: 673049.92 | C30: 868765.75
A32: CLIENTES TRASPASADOS
A33: CONFECCIONES LANCASTER | B33: 68410.64 | C33: 125053.4
A35: QUITANDO LOS CLIENTES
A36: Suma de IMPORTE (S/.) | B36: MESES
A37: ASESOR | B37: ENERO | C37: FEBRERO
A38: DIANA MARCOS | B38: =+B30-B33 -> 604639.28 | C38: =+C30-C33 -> 743712.35
A41: ALFREDO ASTOQUILLCA
A42: ACTUALMENTE
A43: Suma de IMPORTE (S/.) | B43: MESES
A44: ASESOR | B44: ENERO | C44: FEBRERO
A45: ALFREDO ASTOQUILLCA | B45: 622444.2 | C45: 770345.13
A47: CLIENTES TRASPASADOS
A48: BERNACHEA CARHUACHUCO MAURICIO | B48: 2197.5
A49: COOPERATIVA INDUSTRIAL MANUFACTURAS TRES ESTRELLAS LTDA | B49: 11483.61
A50: DORA CONROY S.R.L. | C50: 3376.82
A51: VALENCIA CARITA GUIDO | B51: 1620
...

Sheet 2025
A1: 2025
A2: ANTONIO CHAVEZ
A3: ACTUALMENTE
A4: Suma de IMPORTE (S/.) | B4: MESES
A5: ASESOR | B5: OCTUBRE | C5: NOVIEMBRE | D5: DICIEMBRE
A6: ANTONIO CHAVEZ | B6: 1179063.1 | C6: 768063.99 | D6: 397922.08
A8: CLIENTES TRASPASADOS
A9: ROYAL KNIT SAC | B9: 3353.15 | C9: 27107.7
A10: TEXGROUP | B10: 62305.24 | C10: 25122.8 | D10: 21559.29
A11: TEXTIL DEL VALLE | B11: 79156.18 | C11: 53726.91 | D11: 38586.34
B12: =+SUM(B9:B11) -> 144814.57 | C12: =+SUM(C9:C11) -> 105957.41 | D12: =+SUM(D9:D11) -> 60145.63
A14: QUITANDO LOS CLIENTES
A15: Suma de IMPORTE (S/.) | B15: MESES
A16: ASESOR | B16: OCTUBRE | C16: NOVIEMBRE | D16: DICIEMBRE
A17: ANTONIO CHAVEZ | B17: =+B6-B12 -> 1034248.5 | C17: =+C6-C12 -> 662106.58 | D17: =+D6-D12 -> 337776.45
A21: DIANA MARCOS
A22: ACTUALMENTE
A23: Suma de IMPORTE (S/.) | B23: MESES
A24: ASESOR | B24: OCTUBRE | C24: NOVIEMBRE | D24: DICIEMBRE
A25: DIANA MARCOS | B25: 956424.59 | C25: 908274.77 | D25: 614371.24
A27: CLIENTES TRASPASADOS
A28: CONFECCIONES LANCASTER | B28: 400027.94 | C28: 139773.11 | D28: 41306.77
A29: SUR COLOR | B29: 13760.54 | C29: 22481.16
B30: =+SUM(B27:B29) -> 413788.48 | C30: =+SUM(C27:C29) -> 162254.27
A31: QUITANDO LOS CLIENTES
A32: Suma de IMPORTE (S/.) | B32: MESES
A33: ASESOR | B33: OCTUBRE | C33: NOVIEMBRE | D33: DICIEMBRE
A34: DIANA MARCOS | B34: =+B25-B30 -> 542636.11 | C34: =+C25-C30 -> 746020.5 | D34: =+D25-D28 -> 573064.47
A37: ALFREDO ASTOQUILLCA
A38: ACTUALMENTE
A39: Suma de IMPORTE (S/.) | B39: MESES
A40: ASESOR | B40: OCTUBRE | C40: NOVIEMBRE | D40: DICIEMBRE
A41: ALFREDO ASTOQUILLCA | B41: 758662.56 | C41: 731095.83 | D41: 675661.97
A43: CLIENTES TRASPASADOS
A44: CINTAS TEXTILES DEL PERU S.A.C. | B44: 46068.04
A45: COOPERATIVA INDUSTRIAL MANUFACTURAS TRES ESTRELLAS LTDA | B45: 15204.48 | C45: 26241.73 | D45: 11739.82
A46: COTTON CREATIONS SAC | C46: 436.2
A47: DORA CONROY S.R.L | B47: 686.25 | C47: 1196.49
A48: HUAMAN HERRERA DE YA¥EZ MARIA LUISA | B48: 11813.36
A49: VENATOR | B49: 42854.33 | C49: 72290.38 | D49: 165254.09
...

Sheet COMP_MEN_ASES 2024
A3: IMPORTE (S/.) POR ASESOR | B3: ASESOR
A4: MES | B4: ALFREDO ASTOQUILLCA | C4: FATIMA VARA | D4: JUAN MEDINA | E4: RAQUEL BRAVO | F4: Total general
A5: ENERO | B5: 439540.08 | C5: 581584.06 | D5: 1064002 | E5: 494540.86 | F5: 2579667
A6: FEBRERO | B6: 550082.68 | C6: 528241.89 | D6: 1877299.8 | E6: 487698.46 | F6: 3443322.8
A7: MARZO | B7: 553802.6 | C7: 887878.26 | D7: 1035890.4 | E7: 778937.63 | F7: 3256508.9
A8: ABRIL | B8: 561735.9 | C8: 1436877.7 | D8: 1322449.5 | E8: 737232.8 | F8: 4058295.9
A9: MAYO | B9: 467928.04 | C9: 1558190.8 | D9: 1548776.9 | E9: 696573.79 | F9: 4271469.5
A10: JUNIO | B10: 530121.33 | C10: 982569.52 | D10: 1344399.8 | E10: 823436.69 | F10: 3680527.3
A11: JULIO | B11: 580804.49 | C11: 1218876.3 | D11: 1220009.9 | E11: 1118815.4 | F11: 4138506.1
A12: AGOSTO | B12: 563635.78 | C12: 1169164.2 | D12: 1258690.4 | E12: 1105635.7 | F12: 4097126
A13: SETIEMBRE | B13: 548585.11 | C13: 949706.26 | D13: 1306141.6 | E13: 800137.88 | F13: 3604570.9
A14: OCTUBRE | B14: 655994.05 | C14: 1265005.7 | D14: 1827020 | E14: 382986.05 | F14: 4131005.8
A15: NOVIEMBRE | B15: 593813.28 | C15: 1232407.5 | D15: 1606493.2 | E15: 517098.34 | F15: 3949812.4
A16: DICIEMBRE | B16: 525928.78 | C16: 911669.06 | D16: 1073107.9 | E16: 477987.13 | F16: 2988692.8
A17: Total general | B17: 6571972.1 | C17: 12722171 | D17: 16484281 | E17: 8421080.7 | F17: 44199505
A19: CANTIDAD (KG) POR ASESOR | B19: ASESOR
A20: MES | B20: ALFREDO ASTOQUILLCA | C20: FATIMA VARA | D20: JUAN MEDINA | E20: RAQUEL BRAVO | F20: Total general
A21: ENERO | B21: 12001.47 | C21: 0 | D21: 20573.6 | E21: 13367.82 | F21: 45942.89
A22: FEBRERO | B22: 15670.28 | C22: 11886.59 | D22: 35798.43 | E22: 9816.74 | F22: 73172.04
A23: MARZO | B23: 17184.68 | C23: 22332.92 | D23: 21612.87 | E23: 16121.28 | F23: 77251.75
A24: ABRIL | B24: 20315.51 | C24: 26459.21 | D24: 27544.4 | E24: 13336.39 | F24: 87655.51
A25: MAYO | B25: 13845.45 | C25: 30308.09 | D25: 37310.93 | E25: 15336.59 | F25: 96801.06
A26: JUNIO | B26: 17442.29 | C26: 15750.06 | D26: 32858.22 | E26: 18434.72 | F26: 84485.29
A27: JULIO | B27: 17351.08 | C27: 17168.19 | D27: 37091.15 | E27: 21902.33 | F27: 93512.75
A28: AGOSTO | B28: 19969.31 | C28: 19484.79 | D28: 28867.01 | E28: 20430.32 | F28: 88751.43
A29: SETIEMBRE | B29: 17686.23 | C29: 18931.15 | D29: 24303.52 | E29: 15455.26 | F29: 76376.16
A30: OCTUBRE | B30: 17722.19 | C30: 30226.8 | D30: 29726.2 | E30: 7871.02 | F30: 85546.21
A31: NOVIEMBRE | B31: 14137.79 | C31: 28480.46 | D31: 28164.94 | E31: 10892.12 | F31: 81675.31
A32: DICIEMBRE | B32: 14715.57 | C32: 20725.95 | D32: 19185.9 | E32: 9718.93 | F32: 64346.35
A33: Total general | B33: 198041.85 | C33: 241754.21 | D33: 343037.17 | E33: 172683.52 | F33: 955516.75

Sheet COMPARATIVO ANUAL 
A3: IMPORTE ANUAL POR ASESOR | B3: año
A4: Etiquetas de fila | B4: 2024 | C4: 2025 | D4: Total general
A5: A.ASTOQUILLCA | B5: 7454720.2 | C5: 2644292.7 | D5: 10099013
A6: F.VARA | B6: 12741439 | C6: 3414994.1 | D6: 16156433
A7: J.MEDINA | B7: 16560818 | C7: 5493339 | D7: 22054157
A8: A.CHAVEZ | B8: 8415197.2 | C8: 3121268.1 | D8: 11536465
A9: Total general | B9: 45172175 | C9: 14673894 | D9: 59846068

Sheet DATA MENSUAL_ASESOR2024
A1: ASESOR | B1: MES | C1: IMPORTE (S/.) | D1: CANTIDAD (KG)
A2: ALFREDO ASTOQUILLCA | B2: ENERO | C2: 439540.08 | D2: 12001.47
A3: ALFREDO ASTOQUILLCA | B3: FEBRERO | C3: 550082.68 | D3: 15670.28
A4: ALFREDO ASTOQUILLCA | B4: MARZO | C4: 553802.6 | D4: 17184.68
A5: ALFREDO ASTOQUILLCA | B5: ABRIL | C5: 561735.9 | D5: 20315.51
A6: ALFREDO ASTOQUILLCA | B6: MAYO | C6: 467928.04 | D6: 13845.45
A7: ALFREDO ASTOQUILLCA | B7: JUNIO | C7: 530121.33 | D7: 17442.29
A8: ALFREDO ASTOQUILLCA | B8: JULIO | C8: 580804.49 | D8: 17351.08
A9: ALFREDO ASTOQUILLCA | B9: AGOSTO | C9: 563635.78 | D9: 19969.31
A10: ALFREDO ASTOQUILLCA | B10: SETIEMBRE | C10: 548585.11 | D10: 17686.23
A11: ALFREDO ASTOQUILLCA | B11: OCTUBRE | C11: 655994.05 | D11: 17722.19
A12: ALFREDO ASTOQUILLCA | B12: NOVIEMBRE | C12: 593813.28 | D12: 14137.79
A13: ALFREDO ASTOQUILLCA | B13: DICIEMBRE | C13: 525928.78 | D13: 14715.57
... A49: RAQUEL BRAVO | B49: DICIEMBRE | C49: 477987.13 | D49: 9718.93

Sheet DATA ANUAL
A1: COD_CLIENTE | B1: AÑO | C1: NOMBRE | D1: RUC | E1: VENDEDOR | F1: IMPORTE
A2: 20609680378 | B2: 2024 | C2: J & R COMPANY TEXTIL S.A.C. | D2: 20609680378 | E2: J.MEDINA | F2: 4357.178
A3: 20609680378 | B3: 2025 | C3: J & R COMPANY TEXTIL S.A.C. | D3: 20609680378 | E3: J.MEDINA | F3: 10488.62
A4: 20513176 | B4: 2024 | C4: ABLIMATEX EXPORT S.A.C. | D4: 20513176962 | E4: A.CHAVEZ | F4: 11404.87
A5: 20538433790 | B5: 2024 | C5: ABUCORP PERU SAC | D5: 20538433790 | E5: F.VARA | F5: 11234.919
A6: 9410125 | B6: 2024 | C6: ACEVEDO SALAZAR LUIS | D6: 9410125 | E6: A.ASTOQUILLCA | F6: 3016.5119
A7: 20601968 | B7: 2024 | C7: ADOMA S.A.C. | D7: 20601968551 | E7: A.ASTOQUILLCA | F7: 94042.647
A8: 20601968 | B8: 2025 | C8: ADOMA S.A.C. | D8: 20601968551 | E8: A.ASTOQUILLCA | F8: 50933.005
A9: 20512110 | B9: 2024 | C9: AGROFIL HUYRO S.A.C | D9: 20512110143 | E9: A.CHAVEZ | F9: 45513.43
A10: 20512110 | B10: 2025 | C10: AGROFIL HUYRO S.A.C | D10: 20512110143 | E10: A.CHAVEZ | F10: 25191.446
A11: 10166763580 | B11: 2024 | C11: ALBURQUERQUE MERINO MARTHA | D11: 10166763580 | E11: A.CHAVEZ | F11: 16118.046
A12: 20506528 | B12: 2025 | C12: ALDAL CORPORATION E.I.R.L. | D12: 20506528314 | E12: A.ASTOQUILLCA | F12: 22115.678
A13: 72632867 | B13: 2024 | C13: ALFARO BAZAN ANA PAULA | D13: 72632867 | E13: OFICINA | F13: 1046.4671
... A280: 20513382 | B280: 2025 | C280: LA COTONNADE S.A.C. | D280: 20513382279 | E280: OFICINA | F280: 2943.864
A281: 12.385.440-3 | B281: 2024 | C281: LEIVA DIAZ PATRICIO ESTEBAN | D281: 123854403 | E281: A.CHAVEZ | F281: 22650
A282: 20502141 | B282: 2024 | C282: LENNY KIDS S.A.C. | D282: 20502141768 | E282: F.VARA | F282: 66090.87
A283: 20502141 | B283: 2025 | C283: LENNY KIDS S.A.C. | D283: 20502141768 | E283: F.VARA | F283: 23117.476
A284: 20102089 | B284: 2024 | C284: LIVES S.A.C. | D284: 20102089635 | E284: J.MEDINA | F284: 4804393.7
A285: 20102089 | B285: 2025 | C285: LIVES S.A.C. | D285: 20102089635 | E285: J.MEDINA | F285: 710122.97
A286: 20553302049 | B286: 2024 | C286: LOMAS PREMIUM S.A.C. | D286: 20553302049 | E286: A.ASTOQUILLCA | F286: 70783.017
A287: 20553302049 | B287: 2025 | C287: LOMAS PREMIUM S.A.C. | D287: 20553302049 | E287: A.ASTOQUILLCA | F287: 17176.4
A288: 10712426255 | B288: 2025 | C288: LOYOLA ACUÑA NOREMAN SCOTT | D288: 10712426255 | E288: OFICINA | F288: 93.618
A289: 10489683615 | B289: 2024 | C289: LUCIANO MURGA EDSON AARON | D289: 10489683615 | E289: A.ASTOQUILLCA | F289: 437287.41
A290: 10489683615 | B290: 2025 | C290: LUCIANO MURGA EDSON AARON | D290: 10489683615 | E290: A.ASTOQUILLCA | F290: 238550.44
A291: 20606097787 | B291: 2024 | C291: LYON APPAREL MANUFACTURING S.A.C. | D291: 20606097787 | E291: B.CRUZ | F291: 13070.81
A292: 20608299115 | B292: 2024 | C292: MAGIC IN COTTON S.A.C. | D292: 20608299115 | E292: A.CHAVEZ | F292: 5262.7476
A293: 41584475 | B293: 2024 | C293: MALLMA GARCIA ROBERT LUIS | D293: 41584475 | E293: OFICINA | F293: 1551.38
... A516: 20611391545 | B516: 2024 | C516: ZIPPER TRADING R Y A FCO E.I.R.L. | D516: 20611391545 | E516: A.ASTOQUILLCA | F516: 43548.689

Sheet VOLUMEN DE VENTAS
A1: Establecer el periodo de tiempo que se va medir el volumen de ventas: Diario, semanal, mensual o trimestral.
A2: Establecer qué se va medir, puede ser e unidades vendidas o valor monetario.
A3: Establecer la meta: Basarse en el histórico de ventas, proyecciones de crecimiento y las capacidades del equipo.
A4: Por ejemplo si el volumen de ventas promedio es de 1000 unidades mensuales, se puede establecer en una meta de crecimiemto del 10%, lo que llevaria a una meta de 1100 und mensuales.
A5: DEBE SER MEDIBLE
A6: Herramienta de Medicion: Sistema ERP SIGE
A7: MONITOREO, revisión mensual del volumen de ventas para comparar con la meta.
